<robot name = "robot">
    <link name="Link0">
        <inertial>
            <origin xyz="0 0 0.6626256040707136" rpy="0 0 0"/>
            <mass value="1" />
            <inertia ixx="100" ixy="0" ixz="0" iyy="100" iyz="0" izz="100" />
        </inertial>
        <visual>
            <origin xyz="0 0 0.6626256040707136" rpy="0 0 0"/>
            <geometry>
                <box size="0.7372393683086631 0.9860217764693185 1.3252512081414272" />
            </geometry>
            <material name="Green">
                <color rgba="0.25 0.76 0.50 1.0"/>
            </material>
        </visual>
        <collision>
            <origin xyz="0 0 0.6626256040707136" rpy="0 0 0"/>
            <geometry>
                <box size="0.7372393683086631 0.9860217764693185 1.3252512081414272" />
            </geometry>
        </collision>
    </link>
    <joint name="Link0_Link1" type="revolute">
       <parent link="Link0"/>
       <child  link="Link1"/>
       <origin rpy="0 0 0" xyz="0 0.4930108882346593 0.6626256040707136" />
       <axis xyz="0 1 0"/>
       <limit effort="0.0" lower="-3.14159" upper="3.14159" velocity="0.0"/>
    </joint>
    <link name="Link1">
        <inertial>
            <origin xyz="0 0.616454953895755 0" rpy="0 0 0"/>
            <mass value="1" />
            <inertia ixx="100" ixy="0" ixz="0" iyy="100" iyz="0" izz="100" />
        </inertial>
        <visual>
            <origin xyz="0 0.616454953895755 0" rpy="0 0 0"/>
            <geometry>
                <box size="0.7462800937389179 1.23290990779151 0.7952695306629814" />
            </geometry>
            <material name="Blue">
                <color rgba="0.01 0.54 1.0 1.0"/>
            </material>
        </visual>
        <collision>
            <origin xyz="0 0.616454953895755 0" rpy="0 0 0"/>
            <geometry>
                <box size="0.7462800937389179 1.23290990779151 0.7952695306629814" />
            </geometry>
        </collision>
    </link>
    <joint name="Link1_Link1Link00" type="revolute">
       <parent link="Link1"/>
       <child  link="Link1Link00"/>
       <origin rpy="0 0 0" xyz="0.37314004686945895 0.616454953895755 0.0" />
       <axis xyz="0 1 0"/>
       <limit effort="0.0" lower="-3.14159" upper="3.14159" velocity="0.0"/>
    </joint>
    <link name="Link1Link00">
        <inertial>
            <origin xyz="0.40668394071641445 0.0 0.0" rpy="0 0 0"/>
            <mass value="1" />
            <inertia ixx="100" ixy="0" ixz="0" iyy="100" iyz="0" izz="100" />
        </inertial>
        <visual>
            <origin xyz="0.40668394071641445 0.0 0.0" rpy="0 0 0"/>
            <geometry>
                <box size="0.8133678814328289 0.8903536058734374 0.7482585009273139" />
            </geometry>
            <material name="Blue">
                <color rgba="0.01 0.54 1.0 1.0"/>
            </material>
        </visual>
        <collision>
            <origin xyz="0.40668394071641445 0.0 0.0" rpy="0 0 0"/>
            <geometry>
                <box size="0.8133678814328289 0.8903536058734374 0.7482585009273139" />
            </geometry>
        </collision>
    </link>
    <joint name="Link1_Link1Link10" type="revolute">
       <parent link="Link1"/>
       <child  link="Link1Link10"/>
       <origin rpy="0 0 0" xyz="-0.37314004686945895 0.616454953895755 0.0" />
       <axis xyz="0 1 0"/>
       <limit effort="0.0" lower="-3.14159" upper="3.14159" velocity="0.0"/>
    </joint>
    <link name="Link1Link10">
        <inertial>
            <origin xyz="-0.36730145929131175 0.0 0.0" rpy="0 0 0"/>
            <mass value="1" />
            <inertia ixx="100" ixy="0" ixz="0" iyy="100" iyz="0" izz="100" />
        </inertial>
        <visual>
            <origin xyz="-0.36730145929131175 0.0 0.0" rpy="0 0 0"/>
            <geometry>
                <box size="0.7346029185826235 0.8696498968087938 0.5477988584506501" />
            </geometry>
            <material name="Blue">
                <color rgba="0.01 0.54 1.0 1.0"/>
            </material>
        </visual>
        <collision>
            <origin xyz="-0.36730145929131175 0.0 0.0" rpy="0 0 0"/>
            <geometry>
                <box size="0.7346029185826235 0.8696498968087938 0.5477988584506501" />
            </geometry>
        </collision>
    </link>
    <joint name="Link1Link10_Link1Link11" type="revolute">
       <parent link="Link1Link10"/>
       <child  link="Link1Link11"/>
       <origin rpy="0 0 0" xyz="-0.7346029185826235 0.0 0.0" />
       <axis xyz="0 1 0"/>
       <limit effort="0.0" lower="-3.14159" upper="3.14159" velocity="0.0"/>
    </joint>
    <link name="Link1Link11">
        <inertial>
            <origin xyz="-0.36730145929131175 0.0 0.0" rpy="0 0 0"/>
            <mass value="1" />
            <inertia ixx="100" ixy="0" ixz="0" iyy="100" iyz="0" izz="100" />
        </inertial>
        <visual>
            <origin xyz="-0.36730145929131175 0.0 0.0" rpy="0 0 0"/>
            <geometry>
                <box size="0.7346029185826235 0.8696498968087938 0.5477988584506501" />
            </geometry>
            <material name="Green">
                <color rgba="0.25 0.76 0.50 1.0"/>
            </material>
        </visual>
        <collision>
            <origin xyz="-0.36730145929131175 0.0 0.0" rpy="0 0 0"/>
            <geometry>
                <box size="0.7346029185826235 0.8696498968087938 0.5477988584506501" />
            </geometry>
        </collision>
    </link>
</robot>