<robot name = "robot">
    <link name="Link0">
        <inertial>
            <origin xyz="0 0 0.3535139071052272" rpy="0 0 0"/>
            <mass value="1" />
            <inertia ixx="100" ixy="0" ixz="0" iyy="100" iyz="0" izz="100" />
        </inertial>
        <visual>
            <origin xyz="0 0 0.3535139071052272" rpy="0 0 0"/>
            <geometry>
                <box size="1.4157093807651173 0.5812993147661981 0.7070278142104544" />
            </geometry>
            <material name="Green">
                <color rgba="0.25 0.76 0.50 1.0"/>
            </material>
        </visual>
        <collision>
            <origin xyz="0 0 0.3535139071052272" rpy="0 0 0"/>
            <geometry>
                <box size="1.4157093807651173 0.5812993147661981 0.7070278142104544" />
            </geometry>
        </collision>
    </link>
    <joint name="Link0_Link1" type="revolute">
       <parent link="Link0"/>
       <child  link="Link1"/>
       <origin rpy="0 0 0" xyz="0 0.29064965738309906 0.5264931743973162" />
       <axis xyz="0 1 0"/>
       <limit effort="0.0" lower="-3.14159" upper="3.14159" velocity="0.0"/>
    </joint>
    <link name="Link1">
        <inertial>
            <origin xyz="0 0.5337838533501529 0" rpy="0 0 0"/>
            <mass value="1" />
            <inertia ixx="100" ixy="0" ixz="0" iyy="100" iyz="0" izz="100" />
        </inertial>
        <visual>
            <origin xyz="0 0.5337838533501529 0" rpy="0 0 0"/>
            <geometry>
                <box size="0.8706089867073822 1.0675677067003058 1.0529863487946325" />
            </geometry>
            <material name="Blue">
                <color rgba="0.01 0.54 1.0 1.0"/>
            </material>
        </visual>
        <collision>
            <origin xyz="0 0.5337838533501529 0" rpy="0 0 0"/>
            <geometry>
                <box size="0.8706089867073822 1.0675677067003058 1.0529863487946325" />
            </geometry>
        </collision>
    </link>
    <joint name="Link1_Link1Link00" type="revolute">
       <parent link="Link1"/>
       <child  link="Link1Link00"/>
       <origin rpy="0 0 0" xyz="0.4353044933536911 0.5337838533501529 0.0" />
       <axis xyz="0 1 0"/>
       <limit effort="0.0" lower="-3.14159" upper="3.14159" velocity="0.0"/>
    </joint>
    <link name="Link1Link00">
        <inertial>
            <origin xyz="0.40929495260150034 0.0 0.0" rpy="0 0 0"/>
            <mass value="1" />
            <inertia ixx="100" ixy="0" ixz="0" iyy="100" iyz="0" izz="100" />
        </inertial>
        <visual>
            <origin xyz="0.40929495260150034 0.0 0.0" rpy="0 0 0"/>
            <geometry>
                <box size="0.8185899052030007 0.9246751373048065 0.8499030573384032" />
            </geometry>
            <material name="Blue">
                <color rgba="0.01 0.54 1.0 1.0"/>
            </material>
        </visual>
        <collision>
            <origin xyz="0.40929495260150034 0.0 0.0" rpy="0 0 0"/>
            <geometry>
                <box size="0.8185899052030007 0.9246751373048065 0.8499030573384032" />
            </geometry>
        </collision>
    </link>
    <joint name="Link1Link00_Link1Link01" type="revolute">
       <parent link="Link1Link00"/>
       <child  link="Link1Link01"/>
       <origin rpy="0 0 0" xyz="0.8185899052030007 0.0 0.0" />
       <axis xyz="0 1 0"/>
       <limit effort="0.0" lower="-3.14159" upper="3.14159" velocity="0.0"/>
    </joint>
    <link name="Link1Link01">
        <inertial>
            <origin xyz="0.40929495260150034 0.0 0.0" rpy="0 0 0"/>
            <mass value="1" />
            <inertia ixx="100" ixy="0" ixz="0" iyy="100" iyz="0" izz="100" />
        </inertial>
        <visual>
            <origin xyz="0.40929495260150034 0.0 0.0" rpy="0 0 0"/>
            <geometry>
                <box size="0.8185899052030007 0.9246751373048065 0.8499030573384032" />
            </geometry>
            <material name="Blue">
                <color rgba="0.01 0.54 1.0 1.0"/>
            </material>
        </visual>
        <collision>
            <origin xyz="0.40929495260150034 0.0 0.0" rpy="0 0 0"/>
            <geometry>
                <box size="0.8185899052030007 0.9246751373048065 0.8499030573384032" />
            </geometry>
        </collision>
    </link>
    <joint name="Link1_Link1Link10" type="revolute">
       <parent link="Link1"/>
       <child  link="Link1Link10"/>
       <origin rpy="0 0 0" xyz="-0.4353044933536911 0.5337838533501529 0.0" />
       <axis xyz="0 1 0"/>
       <limit effort="0.0" lower="-3.14159" upper="3.14159" velocity="0.0"/>
    </joint>
    <link name="Link1Link10">
        <inertial>
            <origin xyz="-0.38825720370344396 0.0 0.0" rpy="0 0 0"/>
            <mass value="1" />
            <inertia ixx="100" ixy="0" ixz="0" iyy="100" iyz="0" izz="100" />
        </inertial>
        <visual>
            <origin xyz="-0.38825720370344396 0.0 0.0" rpy="0 0 0"/>
            <geometry>
                <box size="0.7765144074068879 0.8509303455009113 0.8030099225829541" />
            </geometry>
            <material name="Green">
                <color rgba="0.25 0.76 0.50 1.0"/>
            </material>
        </visual>
        <collision>
            <origin xyz="-0.38825720370344396 0.0 0.0" rpy="0 0 0"/>
            <geometry>
                <box size="0.7765144074068879 0.8509303455009113 0.8030099225829541" />
            </geometry>
        </collision>
    </link>
    <joint name="Link1Link10_Link1Link11" type="revolute">
       <parent link="Link1Link10"/>
       <child  link="Link1Link11"/>
       <origin rpy="0 0 0" xyz="-0.7765144074068879 0.0 0.0" />
       <axis xyz="0 1 0"/>
       <limit effort="0.0" lower="-3.14159" upper="3.14159" velocity="0.0"/>
    </joint>
    <link name="Link1Link11">
        <inertial>
            <origin xyz="-0.38825720370344396 0.0 0.0" rpy="0 0 0"/>
            <mass value="1" />
            <inertia ixx="100" ixy="0" ixz="0" iyy="100" iyz="0" izz="100" />
        </inertial>
        <visual>
            <origin xyz="-0.38825720370344396 0.0 0.0" rpy="0 0 0"/>
            <geometry>
                <box size="0.7765144074068879 0.8509303455009113 0.8030099225829541" />
            </geometry>
            <material name="Blue">
                <color rgba="0.01 0.54 1.0 1.0"/>
            </material>
        </visual>
        <collision>
            <origin xyz="-0.38825720370344396 0.0 0.0" rpy="0 0 0"/>
            <geometry>
                <box size="0.7765144074068879 0.8509303455009113 0.8030099225829541" />
            </geometry>
        </collision>
    </link>
    <joint name="Link1_Link1Link20" type="revolute">
       <parent link="Link1"/>
       <child  link="Link1Link20"/>
       <origin rpy="0 0 0" xyz="0.0 0.5337838533501529 0.5264931743973162" />
       <axis xyz="0 1 0"/>
       <limit effort="0.0" lower="-3.14159" upper="3.14159" velocity="0.0"/>
    </joint>
    <link name="Link1Link20">
        <inertial>
            <origin xyz="0.0 0.0 0.3702505373810069" rpy="0 0 0"/>
            <mass value="1" />
            <inertia ixx="100" ixy="0" ixz="0" iyy="100" iyz="0" izz="100" />
        </inertial>
        <visual>
            <origin xyz="0.0 0.0 0.3702505373810069" rpy="0 0 0"/>
            <geometry>
                <box size="0.5802598576575968 0.5051869658178993 0.7405010747620138" />
            </geometry>
            <material name="Green">
                <color rgba="0.25 0.76 0.50 1.0"/>
            </material>
        </visual>
        <collision>
            <origin xyz="0.0 0.0 0.3702505373810069" rpy="0 0 0"/>
            <geometry>
                <box size="0.5802598576575968 0.5051869658178993 0.7405010747620138" />
            </geometry>
        </collision>
    </link>
    <joint name="Link1Link20_Link1Link21" type="revolute">
       <parent link="Link1Link20"/>
       <child  link="Link1Link21"/>
       <origin rpy="0 0 0" xyz="0.0 0.0 0.7405010747620138" />
       <axis xyz="0 1 0"/>
       <limit effort="0.0" lower="-3.14159" upper="3.14159" velocity="0.0"/>
    </joint>
    <link name="Link1Link21">
        <inertial>
            <origin xyz="0.0 0.0 0.3702505373810069" rpy="0 0 0"/>
            <mass value="1" />
            <inertia ixx="100" ixy="0" ixz="0" iyy="100" iyz="0" izz="100" />
        </inertial>
        <visual>
            <origin xyz="0.0 0.0 0.3702505373810069" rpy="0 0 0"/>
            <geometry>
                <box size="0.5802598576575968 0.5051869658178993 0.7405010747620138" />
            </geometry>
            <material name="Green">
                <color rgba="0.25 0.76 0.50 1.0"/>
            </material>
        </visual>
        <collision>
            <origin xyz="0.0 0.0 0.3702505373810069" rpy="0 0 0"/>
            <geometry>
                <box size="0.5802598576575968 0.5051869658178993 0.7405010747620138" />
            </geometry>
        </collision>
    </link>
</robot>