<robot name = "robot">
    <link name="Link0">
        <inertial>
            <origin xyz="0 0 0.6626256040707136" rpy="0 0 0"/>
            <mass value="1" />
            <inertia ixx="100" ixy="0" ixz="0" iyy="100" iyz="0" izz="100" />
        </inertial>
        <visual>
            <origin xyz="0 0 0.6626256040707136" rpy="0 0 0"/>
            <geometry>
                <box size="0.7372393683086631 0.9860217764693185 1.3252512081414272" />
            </geometry>
            <material name="Green">
                <color rgba="0.25 0.76 0.50 1.0"/>
            </material>
        </visual>
        <collision>
            <origin xyz="0 0 0.6626256040707136" rpy="0 0 0"/>
            <geometry>
                <box size="0.7372393683086631 0.9860217764693185 1.3252512081414272" />
            </geometry>
        </collision>
    </link>
    <joint name="Link0_Link1" type="revolute">
       <parent link="Link0"/>
       <child  link="Link1"/>
       <origin rpy="0 0 0" xyz="0 0.4930108882346593 0.6626256040707136" />
       <axis xyz="0 1 0"/>
       <limit effort="0.0" lower="-3.14159" upper="3.14159" velocity="0.0"/>
    </joint>
    <link name="Link1">
        <inertial>
            <origin xyz="0 0.479121219011554 0" rpy="0 0 0"/>
            <mass value="1" />
            <inertia ixx="100" ixy="0" ixz="0" iyy="100" iyz="0" izz="100" />
        </inertial>
        <visual>
            <origin xyz="0 0.479121219011554 0" rpy="0 0 0"/>
            <geometry>
                <box size="1.0538558403808853 0.958242438023108 0.7952695306629814" />
            </geometry>
            <material name="Blue">
                <color rgba="0.01 0.54 1.0 1.0"/>
            </material>
        </visual>
        <collision>
            <origin xyz="0 0.479121219011554 0" rpy="0 0 0"/>
            <geometry>
                <box size="1.0538558403808853 0.958242438023108 0.7952695306629814" />
            </geometry>
        </collision>
    </link>
</robot>