<robot name = "robot">
    <link name="Link0">
        <inertial>
            <origin xyz="0 0 0.3687058543746221" rpy="0 0 0"/>
            <mass value="1" />
            <inertia ixx="100" ixy="0" ixz="0" iyy="100" iyz="0" izz="100" />
        </inertial>
        <visual>
            <origin xyz="0 0 0.3687058543746221" rpy="0 0 0"/>
            <geometry>
                <box size="1.2372155746026432 0.6669330246817252 0.7374117087492442" />
            </geometry>
            <material name="Green">
                <color rgba="0.25 0.76 0.50 1.0"/>
            </material>
        </visual>
        <collision>
            <origin xyz="0 0 0.3687058543746221" rpy="0 0 0"/>
            <geometry>
                <box size="1.2372155746026432 0.6669330246817252 0.7374117087492442" />
            </geometry>
        </collision>
    </link>
    <joint name="Link0_Link1" type="revolute">
       <parent link="Link0"/>
       <child  link="Link1"/>
       <origin rpy="0 0 0" xyz="0 0.3334665123408626 0.7174069952736022" />
       <axis xyz="0 1 0"/>
       <limit effort="0.0" lower="-3.14159" upper="3.14159" velocity="0.0"/>
    </joint>
    <link name="Link1">
        <inertial>
            <origin xyz="0 0.3177830520786089 0" rpy="0 0 0"/>
            <mass value="1" />
            <inertia ixx="100" ixy="0" ixz="0" iyy="100" iyz="0" izz="100" />
        </inertial>
        <visual>
            <origin xyz="0 0.3177830520786089 0" rpy="0 0 0"/>
            <geometry>
                <box size="0.6148020974938534 0.6355661041572178 1.4348139905472044" />
            </geometry>
            <material name="Blue">
                <color rgba="0.01 0.54 1.0 1.0"/>
            </material>
        </visual>
        <collision>
            <origin xyz="0 0.3177830520786089 0" rpy="0 0 0"/>
            <geometry>
                <box size="0.6148020974938534 0.6355661041572178 1.4348139905472044" />
            </geometry>
        </collision>
    </link>
    <joint name="Link1_Link1Link00" type="revolute">
       <parent link="Link1"/>
       <child  link="Link1Link00"/>
       <origin rpy="0 0 0" xyz="0.3074010487469267 0.3177830520786089 0.0" />
       <axis xyz="0 1 0"/>
       <limit effort="0.0" lower="-3.14159" upper="3.14159" velocity="0.0"/>
    </joint>
    <link name="Link1Link00">
        <inertial>
            <origin xyz="0.3975611826591768 0.0 0.0" rpy="0 0 0"/>
            <mass value="1" />
            <inertia ixx="100" ixy="0" ixz="0" iyy="100" iyz="0" izz="100" />
        </inertial>
        <visual>
            <origin xyz="0.3975611826591768 0.0 0.0" rpy="0 0 0"/>
            <geometry>
                <box size="0.7951223653183536 0.6355661041572178 0.9454421959214525" />
            </geometry>
            <material name="Blue">
                <color rgba="0.01 0.54 1.0 1.0"/>
            </material>
        </visual>
        <collision>
            <origin xyz="0.3975611826591768 0.0 0.0" rpy="0 0 0"/>
            <geometry>
                <box size="0.7951223653183536 0.6355661041572178 0.9454421959214525" />
            </geometry>
        </collision>
    </link>
    <joint name="Link1Link00_Link1Link01" type="revolute">
       <parent link="Link1Link00"/>
       <child  link="Link1Link01"/>
       <origin rpy="0 0 0" xyz="0.7951223653183536 0.0 0.0" />
       <axis xyz="0 1 0"/>
       <limit effort="0.0" lower="-3.14159" upper="3.14159" velocity="0.0"/>
    </joint>
    <link name="Link1Link01">
        <inertial>
            <origin xyz="0.3975611826591768 0.0 0.0" rpy="0 0 0"/>
            <mass value="1" />
            <inertia ixx="100" ixy="0" ixz="0" iyy="100" iyz="0" izz="100" />
        </inertial>
        <visual>
            <origin xyz="0.3975611826591768 0.0 0.0" rpy="0 0 0"/>
            <geometry>
                <box size="0.7951223653183536 0.8353607727421964 0.9454421959214525" />
            </geometry>
            <material name="Green">
                <color rgba="0.25 0.76 0.50 1.0"/>
            </material>
        </visual>
        <collision>
            <origin xyz="0.3975611826591768 0.0 0.0" rpy="0 0 0"/>
            <geometry>
                <box size="0.7951223653183536 0.8353607727421964 0.9454421959214525" />
            </geometry>
        </collision>
    </link>
    <joint name="Link1_Link1Link10" type="revolute">
       <parent link="Link1"/>
       <child  link="Link1Link10"/>
       <origin rpy="0 0 0" xyz="-0.3074010487469267 0.3177830520786089 0.0" />
       <axis xyz="0 1 0"/>
       <limit effort="0.0" lower="-3.14159" upper="3.14159" velocity="0.0"/>
    </joint>
    <link name="Link1Link10">
        <inertial>
            <origin xyz="-0.26476992354913415 0.0 0.0" rpy="0 0 0"/>
            <mass value="1" />
            <inertia ixx="100" ixy="0" ixz="0" iyy="100" iyz="0" izz="100" />
        </inertial>
        <visual>
            <origin xyz="-0.26476992354913415 0.0 0.0" rpy="0 0 0"/>
            <geometry>
                <box size="0.5295398470982683 0.6355661041572178 0.8063288768615566" />
            </geometry>
            <material name="Blue">
                <color rgba="0.01 0.54 1.0 1.0"/>
            </material>
        </visual>
        <collision>
            <origin xyz="-0.26476992354913415 0.0 0.0" rpy="0 0 0"/>
            <geometry>
                <box size="0.5295398470982683 0.6355661041572178 0.8063288768615566" />
            </geometry>
        </collision>
    </link>
    <joint name="Link1_Link1Link20" type="revolute">
       <parent link="Link1"/>
       <child  link="Link1Link20"/>
       <origin rpy="0 0 0" xyz="0.0 0.3177830520786089 0.7174069952736022" />
       <axis xyz="0 1 0"/>
       <limit effort="0.0" lower="-3.14159" upper="3.14159" velocity="0.0"/>
    </joint>
    <link name="Link1Link20">
        <inertial>
            <origin xyz="0.0 0.0 0.4132294681289242" rpy="0 0 0"/>
            <mass value="1" />
            <inertia ixx="100" ixy="0" ixz="0" iyy="100" iyz="0" izz="100" />
        </inertial>
        <visual>
            <origin xyz="0.0 0.0 0.4132294681289242" rpy="0 0 0"/>
            <geometry>
                <box size="0.5030684908674965 0.6355661041572178 0.8264589362578484" />
            </geometry>
            <material name="Green">
                <color rgba="0.25 0.76 0.50 1.0"/>
            </material>
        </visual>
        <collision>
            <origin xyz="0.0 0.0 0.4132294681289242" rpy="0 0 0"/>
            <geometry>
                <box size="0.5030684908674965 0.6355661041572178 0.8264589362578484" />
            </geometry>
        </collision>
    </link>
</robot>