<robot name = "robot">
    <link name="Link0">
        <inertial>
            <origin xyz="0 0 0.6868541176678338" rpy="0 0 0"/>
            <mass value="1" />
            <inertia ixx="100" ixy="0" ixz="0" iyy="100" iyz="0" izz="100" />
        </inertial>
        <visual>
            <origin xyz="0 0 0.6868541176678338" rpy="0 0 0"/>
                   size="1.1396663905073647 1.3351728317329983 1.3737082353356675">
               </box>
            </geometry>
            <material name="Green">
                <color rgba="0.0 1.0 0.0 1.0"/>
            </material>
        </visual>
        <collision>
            <origin xyz="0 0 0.6868541176678338" rpy="0 0 0"/>
                   size="1.1396663905073647 1.3351728317329983 1.3737082353356675">
               </box>
            </geometry>
        </collision>
    </link>
    <joint name="Link0_Link1" type="revolute">
       <parent link="Link0"/>
       <child  link="Link1"/>
       <origin rpy="0 0 0" xyz="0 0.6675864158664991 0.6868541176678338" />
       <axis xyz="0 1 0"/>
       <limit effort="0.0" lower="-3.14159" upper="3.14159" velocity="0.0"/>
    </joint>
    <link name="Link1">
        <inertial>
            <origin xyz="0 0.28054620185037615 0" rpy="0 0 0"/>
            <mass value="1" />
            <inertia ixx="100" ixy="0" ixz="0" iyy="100" iyz="0" izz="100" />
        </inertial>
        <visual>
            <origin xyz="0 0.28054620185037615 0" rpy="0 0 0"/>
                   size="1.2125191881764517 0.5610924037007523 1.331230361892633">
               </box>
            </geometry>
            <material name="Blue">
                <color rgba="0.0 0.0 1.0 1.0"/>
            </material>
        </visual>
        <collision>
            <origin xyz="0 0.28054620185037615 0" rpy="0 0 0"/>
                   size="1.2125191881764517 0.5610924037007523 1.331230361892633">
               </box>
            </geometry>
        </collision>
    </link>
    <joint name="Link1_Link2" type="revolute">
       <parent link="Link1"/>
       <child  link="Link2"/>
       <origin rpy="0 0 0" xyz="0 0.5610924037007523 0" />
       <axis xyz="0 1 0"/>
       <limit effort="0.0" lower="-3.14159" upper="3.14159" velocity="0.0"/>
    </joint>
    <link name="Link2">
        <inertial>
            <origin xyz="0 0.6989982657871471 0" rpy="0 0 0"/>
            <mass value="1" />
            <inertia ixx="100" ixy="0" ixz="0" iyy="100" iyz="0" izz="100" />
        </inertial>
        <visual>
            <origin xyz="0 0.6989982657871471 0" rpy="0 0 0"/>
                   size="0.9836883942970172 1.3979965315742942 0.8146336655732018">
               </box>
            </geometry>
            <material name="Green">
                <color rgba="0.0 1.0 0.0 1.0"/>
            </material>
        </visual>
        <collision>
            <origin xyz="0 0.6989982657871471 0" rpy="0 0 0"/>
                   size="0.9836883942970172 1.3979965315742942 0.8146336655732018">
               </box>
            </geometry>
        </collision>
    </link>
    <joint name="Link2_Link3" type="revolute">
       <parent link="Link2"/>
       <child  link="Link3"/>
       <origin rpy="0 0 0" xyz="0 1.3979965315742942 0" />
       <axis xyz="0 1 0"/>
       <limit effort="0.0" lower="-3.14159" upper="3.14159" velocity="0.0"/>
    </joint>
    <link name="Link3">
        <inertial>
            <origin xyz="0 0.5416021526631473 0" rpy="0 0 0"/>
            <mass value="1" />
            <inertia ixx="100" ixy="0" ixz="0" iyy="100" iyz="0" izz="100" />
        </inertial>
        <visual>
            <origin xyz="0 0.5416021526631473 0" rpy="0 0 0"/>
                   size="0.9281712672885167 1.0832043053262945 1.2321595291979905">
               </box>
            </geometry>
            <material name="Blue">
                <color rgba="0.0 0.0 1.0 1.0"/>
            </material>
        </visual>
        <collision>
            <origin xyz="0 0.5416021526631473 0" rpy="0 0 0"/>
                   size="0.9281712672885167 1.0832043053262945 1.2321595291979905">
               </box>
            </geometry>
        </collision>
    </link>
</robot>