<robot name = "robot">
    <link name="Link0">
        <inertial>
            <origin xyz="0 0 0.3535139071052272" rpy="0 0 0"/>
            <mass value="1" />
            <inertia ixx="100" ixy="0" ixz="0" iyy="100" iyz="0" izz="100" />
        </inertial>
        <visual>
            <origin xyz="0 0 0.3535139071052272" rpy="0 0 0"/>
            <geometry>
                <box size="1.4157093807651173 0.5812993147661981 0.7070278142104544" />
            </geometry>
            <material name="Green">
                <color rgba="0.25 0.76 0.50 1.0"/>
            </material>
        </visual>
        <collision>
            <origin xyz="0 0 0.3535139071052272" rpy="0 0 0"/>
            <geometry>
                <box size="1.4157093807651173 0.5812993147661981 0.7070278142104544" />
            </geometry>
        </collision>
    </link>
    <joint name="Link0_Link1" type="revolute">
       <parent link="Link0"/>
       <child  link="Link1"/>
       <origin rpy="0 0 0" xyz="0 0.29064965738309906 0.5264931743973162" />
       <axis xyz="0 1 0"/>
       <limit effort="0.0" lower="-3.14159" upper="3.14159" velocity="0.0"/>
    </joint>
    <link name="Link1">
        <inertial>
            <origin xyz="0 0.34194771812277563 0" rpy="0 0 0"/>
            <mass value="1" />
            <inertia ixx="100" ixy="0" ixz="0" iyy="100" iyz="0" izz="100" />
        </inertial>
        <visual>
            <origin xyz="0 0.34194771812277563 0" rpy="0 0 0"/>
            <geometry>
                <box size="0.9438019882998169 0.6838954362455513 1.0529863487946325" />
            </geometry>
            <material name="Blue">
                <color rgba="0.01 0.54 1.0 1.0"/>
            </material>
        </visual>
        <collision>
            <origin xyz="0 0.34194771812277563 0" rpy="0 0 0"/>
            <geometry>
                <box size="0.9438019882998169 0.6838954362455513 1.0529863487946325" />
            </geometry>
        </collision>
    </link>
    <joint name="Link1_Link1Link00" type="revolute">
       <parent link="Link1"/>
       <child  link="Link1Link00"/>
       <origin rpy="0 0 0" xyz="0.47190099414990844 0.34194771812277563 0.0" />
       <axis xyz="0 1 0"/>
       <limit effort="0.0" lower="-3.14159" upper="3.14159" velocity="0.0"/>
    </joint>
    <link name="Link1Link00">
        <inertial>
            <origin xyz="0.3234121764507133 0.0 0.0" rpy="0 0 0"/>
            <mass value="1" />
            <inertia ixx="100" ixy="0" ixz="0" iyy="100" iyz="0" izz="100" />
        </inertial>
        <visual>
            <origin xyz="0.3234121764507133 0.0 0.0" rpy="0 0 0"/>
            <geometry>
                <box size="0.6468243529014266 0.6838954362455513 0.8369803107184287" />
            </geometry>
            <material name="Blue">
                <color rgba="0.01 0.54 1.0 1.0"/>
            </material>
        </visual>
        <collision>
            <origin xyz="0.3234121764507133 0.0 0.0" rpy="0 0 0"/>
            <geometry>
                <box size="0.6468243529014266 0.6838954362455513 0.8369803107184287" />
            </geometry>
        </collision>
    </link>
    <joint name="Link1_Link1Link20" type="revolute">
       <parent link="Link1"/>
       <child  link="Link1Link20"/>
       <origin rpy="0 0 0" xyz="0.0 0.34194771812277563 0.5264931743973162" />
       <axis xyz="0 1 0"/>
       <limit effort="0.0" lower="-3.14159" upper="3.14159" velocity="0.0"/>
    </joint>
    <link name="Link1Link20">
        <inertial>
            <origin xyz="0.0 0.0 0.27109478232144524" rpy="0 0 0"/>
            <mass value="1" />
            <inertia ixx="100" ixy="0" ixz="0" iyy="100" iyz="0" izz="100" />
        </inertial>
        <visual>
            <origin xyz="0.0 0.0 0.27109478232144524" rpy="0 0 0"/>
            <geometry>
                <box size="0.9438019882998169 0.6025402862648834 0.5421895646428905" />
            </geometry>
            <material name="Blue">
                <color rgba="0.01 0.54 1.0 1.0"/>
            </material>
        </visual>
        <collision>
            <origin xyz="0.0 0.0 0.27109478232144524" rpy="0 0 0"/>
            <geometry>
                <box size="0.9438019882998169 0.6025402862648834 0.5421895646428905" />
            </geometry>
        </collision>
    </link>
    <joint name="Link1Link20_Link1Link21" type="revolute">
       <parent link="Link1Link20"/>
       <child  link="Link1Link21"/>
       <origin rpy="0 0 0" xyz="0.0 0.0 0.5421895646428905" />
       <axis xyz="0 1 0"/>
       <limit effort="0.0" lower="-3.14159" upper="3.14159" velocity="0.0"/>
    </joint>
    <link name="Link1Link21">
        <inertial>
            <origin xyz="0.0 0.0 0.27109478232144524" rpy="0 0 0"/>
            <mass value="1" />
            <inertia ixx="100" ixy="0" ixz="0" iyy="100" iyz="0" izz="100" />
        </inertial>
        <visual>
            <origin xyz="0.0 0.0 0.27109478232144524" rpy="0 0 0"/>
            <geometry>
                <box size="0.9438019882998169 0.6025402862648834 0.5421895646428905" />
            </geometry>
            <material name="Green">
                <color rgba="0.25 0.76 0.50 1.0"/>
            </material>
        </visual>
        <collision>
            <origin xyz="0.0 0.0 0.27109478232144524" rpy="0 0 0"/>
            <geometry>
                <box size="0.9438019882998169 0.6025402862648834 0.5421895646428905" />
            </geometry>
        </collision>
    </link>
</robot>