<robot name = "robot">
    <link name="Link0">
        <inertial>
            <origin xyz="0 0 0.6143782666884379" rpy="0 0 0"/>
            <mass value="1" />
            <inertia ixx="100" ixy="0" ixz="0" iyy="100" iyz="0" izz="100" />
        </inertial>
        <visual>
            <origin xyz="0 0 0.6143782666884379" rpy="0 0 0"/>
            <geometry>
                <box size="1.4940387831459498 1.145010171419952 1.2287565333768757" />
            </geometry>
            <material name="Green">
                <color rgba="0.25 0.76 0.50 1.0"/>
            </material>
        </visual>
        <collision>
            <origin xyz="0 0 0.6143782666884379" rpy="0 0 0"/>
            <geometry>
                <box size="1.4940387831459498 1.145010171419952 1.2287565333768757" />
            </geometry>
        </collision>
    </link>
    <joint name="Link0_Link1" type="revolute">
       <parent link="Link0"/>
       <child  link="Link1"/>
       <origin rpy="0 0 0" xyz="0 0.572505085709976 0.6143782666884379" />
       <axis xyz="0 1 0"/>
       <limit effort="0.0" lower="-3.14159" upper="3.14159" velocity="0.0"/>
    </joint>
    <link name="Link1">
        <inertial>
            <origin xyz="0 0.5838093607779014 0" rpy="0 0 0"/>
            <mass value="1" />
            <inertia ixx="100" ixy="0" ixz="0" iyy="100" iyz="0" izz="100" />
        </inertial>
        <visual>
            <origin xyz="0 0.5838093607779014 0" rpy="0 0 0"/>
            <geometry>
                <box size="1.109721737151298 1.1676187215558027 0.8709085641019559" />
            </geometry>
            <material name="Blue">
                <color rgba="0.01 0.54 1.0 1.0"/>
            </material>
        </visual>
        <collision>
            <origin xyz="0 0.5838093607779014 0" rpy="0 0 0"/>
            <geometry>
                <box size="1.109721737151298 1.1676187215558027 0.8709085641019559" />
            </geometry>
        </collision>
    </link>
    <joint name="Link1_Link1Link00" type="revolute">
       <parent link="Link1"/>
       <child  link="Link1Link00"/>
       <origin rpy="0 0 0" xyz="0.554860868575649 0.5838093607779014 0.0" />
       <axis xyz="0 1 0"/>
       <limit effort="0.0" lower="-3.14159" upper="3.14159" velocity="0.0"/>
    </joint>
    <link name="Link1Link00">
        <inertial>
            <origin xyz="0.46285367133287997 0.0 0.0" rpy="0 0 0"/>
            <mass value="1" />
            <inertia ixx="100" ixy="0" ixz="0" iyy="100" iyz="0" izz="100" />
        </inertial>
        <visual>
            <origin xyz="0.46285367133287997 0.0 0.0" rpy="0 0 0"/>
            <geometry>
                <box size="0.9257073426657599 0.6973754379088865 0.9864384493722249" />
            </geometry>
            <material name="Blue">
                <color rgba="0.01 0.54 1.0 1.0"/>
            </material>
        </visual>
        <collision>
            <origin xyz="0.46285367133287997 0.0 0.0" rpy="0 0 0"/>
            <geometry>
                <box size="0.9257073426657599 0.6973754379088865 0.9864384493722249" />
            </geometry>
        </collision>
    </link>
    <joint name="Link1Link00_Link1Link01" type="revolute">
       <parent link="Link1Link00"/>
       <child  link="Link1Link01"/>
       <origin rpy="0 0 0" xyz="0.9257073426657599 0.0 0.0" />
       <axis xyz="0 1 0"/>
       <limit effort="0.0" lower="-3.14159" upper="3.14159" velocity="0.0"/>
    </joint>
    <link name="Link1Link01">
        <inertial>
            <origin xyz="0.46285367133287997 0.0 0.0" rpy="0 0 0"/>
            <mass value="1" />
            <inertia ixx="100" ixy="0" ixz="0" iyy="100" iyz="0" izz="100" />
        </inertial>
        <visual>
            <origin xyz="0.46285367133287997 0.0 0.0" rpy="0 0 0"/>
            <geometry>
                <box size="0.9257073426657599 0.6973754379088865 0.9864384493722249" />
            </geometry>
            <material name="Green">
                <color rgba="0.25 0.76 0.50 1.0"/>
            </material>
        </visual>
        <collision>
            <origin xyz="0.46285367133287997 0.0 0.0" rpy="0 0 0"/>
            <geometry>
                <box size="0.9257073426657599 0.6973754379088865 0.9864384493722249" />
            </geometry>
        </collision>
    </link>
    <joint name="Link1_Link1Link10" type="revolute">
       <parent link="Link1"/>
       <child  link="Link1Link10"/>
       <origin rpy="0 0 0" xyz="-0.554860868575649 0.5838093607779014 0.0" />
       <axis xyz="0 1 0"/>
       <limit effort="0.0" lower="-3.14159" upper="3.14159" velocity="0.0"/>
    </joint>
    <link name="Link1Link10">
        <inertial>
            <origin xyz="-0.38584690544819833 0.0 0.0" rpy="0 0 0"/>
            <mass value="1" />
            <inertia ixx="100" ixy="0" ixz="0" iyy="100" iyz="0" izz="100" />
        </inertial>
        <visual>
            <origin xyz="-0.38584690544819833 0.0 0.0" rpy="0 0 0"/>
            <geometry>
                <box size="0.7716938108963967 0.7886261043177771 0.8140724734918885" />
            </geometry>
            <material name="Blue">
                <color rgba="0.01 0.54 1.0 1.0"/>
            </material>
        </visual>
        <collision>
            <origin xyz="-0.38584690544819833 0.0 0.0" rpy="0 0 0"/>
            <geometry>
                <box size="0.7716938108963967 0.7886261043177771 0.8140724734918885" />
            </geometry>
        </collision>
    </link>
</robot>