<robot name = "robot">
    <link name="Link0">
        <inertial>
            <origin xyz="0 0 0.6478731998153002" rpy="0 0 0"/>
            <mass value="1" />
            <inertia ixx="100" ixy="0" ixz="0" iyy="100" iyz="0" izz="100" />
        </inertial>
        <visual>
            <origin xyz="0 0 0.6478731998153002" rpy="0 0 0"/>
            <geometry>
                <box size="1.0875386362891937 1.2738956745421195 1.2957463996306005" />
            </geometry>
            <material name="Green">
                <color rgba="0.25 0.76 0.50 1.0"/>
            </material>
        </visual>
        <collision>
            <origin xyz="0 0 0.6478731998153002" rpy="0 0 0"/>
            <geometry>
                <box size="1.0875386362891937 1.2738956745421195 1.2957463996306005" />
            </geometry>
        </collision>
    </link>
    <joint name="Link0_Link1" type="revolute">
       <parent link="Link0"/>
       <child  link="Link1"/>
       <origin rpy="0 0 0" xyz="0 0.6369478372710597 0.6609115545369307" />
       <axis xyz="0 1 0"/>
       <limit effort="0.0" lower="-3.14159" upper="3.14159" velocity="0.0"/>
    </joint>
    <link name="Link1">
        <inertial>
            <origin xyz="0 0.6773615155391557 0" rpy="0 0 0"/>
            <mass value="1" />
            <inertia ixx="100" ixy="0" ixz="0" iyy="100" iyz="0" izz="100" />
        </inertial>
        <visual>
            <origin xyz="0 0.6773615155391557 0" rpy="0 0 0"/>
            <geometry>
                <box size="0.6978308953987207 1.3547230310783114 1.3218231090738615" />
            </geometry>
            <material name="Blue">
                <color rgba="0.01 0.54 1.0 1.0"/>
            </material>
        </visual>
        <collision>
            <origin xyz="0 0.6773615155391557 0" rpy="0 0 0"/>
            <geometry>
                <box size="0.6978308953987207 1.3547230310783114 1.3218231090738615" />
            </geometry>
        </collision>
    </link>
    <joint name="Link1_Link1Link00" type="revolute">
       <parent link="Link1"/>
       <child  link="Link1Link00"/>
       <origin rpy="0 0 0" xyz="0.34891544769936034 0.6773615155391557 0.0" />
       <axis xyz="0 1 0"/>
       <limit effort="0.0" lower="-3.14159" upper="3.14159" velocity="0.0"/>
    </joint>
    <link name="Link1Link00">
        <inertial>
            <origin xyz="0.4585676137535424 0.0 0.0" rpy="0 0 0"/>
            <mass value="1" />
            <inertia ixx="100" ixy="0" ixz="0" iyy="100" iyz="0" izz="100" />
        </inertial>
        <visual>
            <origin xyz="0.4585676137535424 0.0 0.0" rpy="0 0 0"/>
            <geometry>
                <box size="0.9171352275070848 0.9420898060605513 0.8444251088480528" />
            </geometry>
            <material name="Blue">
                <color rgba="0.01 0.54 1.0 1.0"/>
            </material>
        </visual>
        <collision>
            <origin xyz="0.4585676137535424 0.0 0.0" rpy="0 0 0"/>
            <geometry>
                <box size="0.9171352275070848 0.9420898060605513 0.8444251088480528" />
            </geometry>
        </collision>
    </link>
    <joint name="Link1Link00_Link1Link01" type="revolute">
       <parent link="Link1Link00"/>
       <child  link="Link1Link01"/>
       <origin rpy="0 0 0" xyz="0.9171352275070848 0.0 0.0" />
       <axis xyz="0 1 0"/>
       <limit effort="0.0" lower="-3.14159" upper="3.14159" velocity="0.0"/>
    </joint>
    <link name="Link1Link01">
        <inertial>
            <origin xyz="0.4585676137535424 0.0 0.0" rpy="0 0 0"/>
            <mass value="1" />
            <inertia ixx="100" ixy="0" ixz="0" iyy="100" iyz="0" izz="100" />
        </inertial>
        <visual>
            <origin xyz="0.4585676137535424 0.0 0.0" rpy="0 0 0"/>
            <geometry>
                <box size="0.9171352275070848 0.9420898060605513 0.8444251088480528" />
            </geometry>
            <material name="Green">
                <color rgba="0.25 0.76 0.50 1.0"/>
            </material>
        </visual>
        <collision>
            <origin xyz="0.4585676137535424 0.0 0.0" rpy="0 0 0"/>
            <geometry>
                <box size="0.9171352275070848 0.9420898060605513 0.8444251088480528" />
            </geometry>
        </collision>
    </link>
    <joint name="Link1_Link1Link20" type="revolute">
       <parent link="Link1"/>
       <child  link="Link1Link20"/>
       <origin rpy="0 0 0" xyz="0.0 0.6773615155391557 0.6609115545369307" />
       <axis xyz="0 1 0"/>
       <limit effort="0.0" lower="-3.14159" upper="3.14159" velocity="0.0"/>
    </joint>
    <link name="Link1Link20">
        <inertial>
            <origin xyz="0.0 0.0 0.4823666573218577" rpy="0 0 0"/>
            <mass value="1" />
            <inertia ixx="100" ixy="0" ixz="0" iyy="100" iyz="0" izz="100" />
        </inertial>
        <visual>
            <origin xyz="0.0 0.0 0.4823666573218577" rpy="0 0 0"/>
            <geometry>
                <box size="0.585979303053987 0.6714563593157967 0.9647333146437154" />
            </geometry>
            <material name="Green">
                <color rgba="0.25 0.76 0.50 1.0"/>
            </material>
        </visual>
        <collision>
            <origin xyz="0.0 0.0 0.4823666573218577" rpy="0 0 0"/>
            <geometry>
                <box size="0.585979303053987 0.6714563593157967 0.9647333146437154" />
            </geometry>
        </collision>
    </link>
    <joint name="Link1Link20_Link1Link21" type="revolute">
       <parent link="Link1Link20"/>
       <child  link="Link1Link21"/>
       <origin rpy="0 0 0" xyz="0.0 0.0 0.9647333146437154" />
       <axis xyz="0 1 0"/>
       <limit effort="0.0" lower="-3.14159" upper="3.14159" velocity="0.0"/>
    </joint>
    <link name="Link1Link21">
        <inertial>
            <origin xyz="0.0 0.0 0.4823666573218577" rpy="0 0 0"/>
            <mass value="1" />
            <inertia ixx="100" ixy="0" ixz="0" iyy="100" iyz="0" izz="100" />
        </inertial>
        <visual>
            <origin xyz="0.0 0.0 0.4823666573218577" rpy="0 0 0"/>
            <geometry>
                <box size="0.585979303053987 0.6714563593157967 0.9647333146437154" />
            </geometry>
            <material name="Blue">
                <color rgba="0.01 0.54 1.0 1.0"/>
            </material>
        </visual>
        <collision>
            <origin xyz="0.0 0.0 0.4823666573218577" rpy="0 0 0"/>
            <geometry>
                <box size="0.585979303053987 0.6714563593157967 0.9647333146437154" />
            </geometry>
        </collision>
    </link>
</robot>