<robot name = "robot">
    <link name="Link0">
        <inertial>
            <origin xyz="0 0 0.4476270858097426" rpy="0 0 0"/>
            <mass value="1" />
            <inertia ixx="100" ixy="0" ixz="0" iyy="100" iyz="0" izz="100" />
        </inertial>
        <visual>
            <origin xyz="0 0 0.4476270858097426" rpy="0 0 0"/>
            <geometry>
                <box size="0.5327833272017751 0.810070998659789 0.8952541716194852" />
            </geometry>
            <material name="Green">
                <color rgba="0.25 0.76 0.50 1.0"/>
            </material>
        </visual>
        <collision>
            <origin xyz="0 0 0.4476270858097426" rpy="0 0 0"/>
            <geometry>
                <box size="0.5327833272017751 0.810070998659789 0.8952541716194852" />
            </geometry>
        </collision>
    </link>
    <joint name="Link0_Link1" type="revolute">
       <parent link="Link0"/>
       <child  link="Link1"/>
       <origin rpy="0 0 0" xyz="0 0.4050354993298945 0.7217233290468306" />
       <axis xyz="1 0 0"/>
       <limit effort="0.0" lower="-3.14159" upper="3.14159" velocity="0.0"/>
    </joint>
    <link name="Link1">
        <inertial>
            <origin xyz="0 0.6314249050438181 0" rpy="0 0 0"/>
            <mass value="1" />
            <inertia ixx="100" ixy="0" ixz="0" iyy="100" iyz="0" izz="100" />
        </inertial>
        <visual>
            <origin xyz="0 0.6314249050438181 0" rpy="0 0 0"/>
            <geometry>
                <box size="0.5395034104727252 1.2628498100876362 1.4434466580936611" />
            </geometry>
            <material name="Blue">
                <color rgba="0.01 0.54 1.0 1.0"/>
            </material>
        </visual>
        <collision>
            <origin xyz="0 0.6314249050438181 0" rpy="0 0 0"/>
            <geometry>
                <box size="0.5395034104727252 1.2628498100876362 1.4434466580936611" />
            </geometry>
        </collision>
    </link>
    <joint name="Link1_Link1Link00" type="revolute">
       <parent link="Link1"/>
       <child  link="Link1Link00"/>
       <origin rpy="0 0 0" xyz="0.2697517052363626 0.6314249050438181 0.0" />
       <axis xyz="1 0 0"/>
       <limit effort="0.0" lower="-3.14159" upper="3.14159" velocity="0.0"/>
    </joint>
    <link name="Link1Link00">
        <inertial>
            <origin xyz="0.35934091049440625 0.0 0.0" rpy="0 0 0"/>
            <mass value="1" />
            <inertia ixx="100" ixy="0" ixz="0" iyy="100" iyz="0" izz="100" />
        </inertial>
        <visual>
            <origin xyz="0.35934091049440625 0.0 0.0" rpy="0 0 0"/>
            <geometry>
                <box size="0.7186818209888125 0.5235780070024592 0.9857889798960802" />
            </geometry>
            <material name="Green">
                <color rgba="0.25 0.76 0.50 1.0"/>
            </material>
        </visual>
        <collision>
            <origin xyz="0.35934091049440625 0.0 0.0" rpy="0 0 0"/>
            <geometry>
                <box size="0.7186818209888125 0.5235780070024592 0.9857889798960802" />
            </geometry>
        </collision>
    </link>
    <joint name="Link1_Link1Link10" type="revolute">
       <parent link="Link1"/>
       <child  link="Link1Link10"/>
       <origin rpy="0 0 0" xyz="-0.2697517052363626 0.6314249050438181 0.0" />
       <axis xyz="1 0 0"/>
       <limit effort="0.0" lower="-3.14159" upper="3.14159" velocity="0.0"/>
    </joint>
    <link name="Link1Link10">
        <inertial>
            <origin xyz="-0.4308174357445371 0.0 0.0" rpy="0 0 0"/>
            <mass value="1" />
            <inertia ixx="100" ixy="0" ixz="0" iyy="100" iyz="0" izz="100" />
        </inertial>
        <visual>
            <origin xyz="-0.4308174357445371 0.0 0.0" rpy="0 0 0"/>
            <geometry>
                <box size="0.8616348714890742 0.9373744369931507 0.99457482167238" />
            </geometry>
            <material name="Green">
                <color rgba="0.25 0.76 0.50 1.0"/>
            </material>
        </visual>
        <collision>
            <origin xyz="-0.4308174357445371 0.0 0.0" rpy="0 0 0"/>
            <geometry>
                <box size="0.8616348714890742 0.9373744369931507 0.99457482167238" />
            </geometry>
        </collision>
    </link>
    <joint name="Link1_Link1Link20" type="revolute">
       <parent link="Link1"/>
       <child  link="Link1Link20"/>
       <origin rpy="0 0 0" xyz="0.0 0.6314249050438181 0.7217233290468306" />
       <axis xyz="1 0 0"/>
       <limit effort="0.0" lower="-3.14159" upper="3.14159" velocity="0.0"/>
    </joint>
    <link name="Link1Link20">
        <inertial>
            <origin xyz="0.0 0.0 0.35626495371271405" rpy="0 0 0"/>
            <mass value="1" />
            <inertia ixx="100" ixy="0" ixz="0" iyy="100" iyz="0" izz="100" />
        </inertial>
        <visual>
            <origin xyz="0.0 0.0 0.35626495371271405" rpy="0 0 0"/>
            <geometry>
                <box size="0.5395034104727252 0.8633343958051043 0.7125299074254281" />
            </geometry>
            <material name="Blue">
                <color rgba="0.01 0.54 1.0 1.0"/>
            </material>
        </visual>
        <collision>
            <origin xyz="0.0 0.0 0.35626495371271405" rpy="0 0 0"/>
            <geometry>
                <box size="0.5395034104727252 0.8633343958051043 0.7125299074254281" />
            </geometry>
        </collision>
    </link>
</robot>