<robot name = "robot">
    <link name="Link0">
        <inertial>
            <origin xyz="0 0 0.45385614524997137" rpy="0 0 0"/>
            <mass value="1" />
            <inertia ixx="100" ixy="0" ixz="0" iyy="100" iyz="0" izz="100" />
        </inertial>
        <visual>
            <origin xyz="0 0 0.45385614524997137" rpy="0 0 0"/>
            <geometry>
                <box size="0.570096270245784 1.1826521699378296 0.9077122904999427" />
            </geometry>
            <material name="Green">
                <color rgba="0.25 0.76 0.50 1.0"/>
            </material>
        </visual>
        <collision>
            <origin xyz="0 0 0.45385614524997137" rpy="0 0 0"/>
            <geometry>
                <box size="0.570096270245784 1.1826521699378296 0.9077122904999427" />
            </geometry>
        </collision>
    </link>
    <joint name="Link0_Link1" type="revolute">
       <parent link="Link0"/>
       <child  link="Link1"/>
       <origin rpy="0 0 0" xyz="0 0.5913260849689148 0.45385614524997137" />
       <axis xyz="0 1 0"/>
       <limit effort="0.0" lower="-3.14159" upper="3.14159" velocity="0.0"/>
    </joint>
    <link name="Link1">
        <inertial>
            <origin xyz="0 0.7327888564775255 0" rpy="0 0 0"/>
            <mass value="1" />
            <inertia ixx="100" ixy="0" ixz="0" iyy="100" iyz="0" izz="100" />
        </inertial>
        <visual>
            <origin xyz="0 0.7327888564775255 0" rpy="0 0 0"/>
            <geometry>
                <box size="0.7982139578681767 1.465577712955051 0.6136868344434776" />
            </geometry>
            <material name="Blue">
                <color rgba="0.01 0.54 1.0 1.0"/>
            </material>
        </visual>
        <collision>
            <origin xyz="0 0.7327888564775255 0" rpy="0 0 0"/>
            <geometry>
                <box size="0.7982139578681767 1.465577712955051 0.6136868344434776" />
            </geometry>
        </collision>
    </link>
    <joint name="Link1_Link1Link00" type="revolute">
       <parent link="Link1"/>
       <child  link="Link1Link00"/>
       <origin rpy="0 0 0" xyz="0.39910697893408836 0.7327888564775255 0.0" />
       <axis xyz="0 1 0"/>
       <limit effort="0.0" lower="-3.14159" upper="3.14159" velocity="0.0"/>
    </joint>
    <link name="Link1Link00">
        <inertial>
            <origin xyz="0.3605348558469548 0.0 0.0" rpy="0 0 0"/>
            <mass value="1" />
            <inertia ixx="100" ixy="0" ixz="0" iyy="100" iyz="0" izz="100" />
        </inertial>
        <visual>
            <origin xyz="0.3605348558469548 0.0 0.0" rpy="0 0 0"/>
            <geometry>
                <box size="0.7210697116939097 0.7553387594611372 0.6883898613724806" />
            </geometry>
            <material name="Blue">
                <color rgba="0.01 0.54 1.0 1.0"/>
            </material>
        </visual>
        <collision>
            <origin xyz="0.3605348558469548 0.0 0.0" rpy="0 0 0"/>
            <geometry>
                <box size="0.7210697116939097 0.7553387594611372 0.6883898613724806" />
            </geometry>
        </collision>
    </link>
    <joint name="Link1_Link1Link10" type="revolute">
       <parent link="Link1"/>
       <child  link="Link1Link10"/>
       <origin rpy="0 0 0" xyz="-0.39910697893408836 0.7327888564775255 0.0" />
       <axis xyz="0 1 0"/>
       <limit effort="0.0" lower="-3.14159" upper="3.14159" velocity="0.0"/>
    </joint>
    <link name="Link1Link10">
        <inertial>
            <origin xyz="-0.27086834241414626 0.0 0.0" rpy="0 0 0"/>
            <mass value="1" />
            <inertia ixx="100" ixy="0" ixz="0" iyy="100" iyz="0" izz="100" />
        </inertial>
        <visual>
            <origin xyz="-0.27086834241414626 0.0 0.0" rpy="0 0 0"/>
            <geometry>
                <box size="0.5417366848282925 0.6231566150932015 0.531598241825199" />
            </geometry>
            <material name="Green">
                <color rgba="0.25 0.76 0.50 1.0"/>
            </material>
        </visual>
        <collision>
            <origin xyz="-0.27086834241414626 0.0 0.0" rpy="0 0 0"/>
            <geometry>
                <box size="0.5417366848282925 0.6231566150932015 0.531598241825199" />
            </geometry>
        </collision>
    </link>
    <joint name="Link1Link10_Link1Link11" type="revolute">
       <parent link="Link1Link10"/>
       <child  link="Link1Link11"/>
       <origin rpy="0 0 0" xyz="-0.5417366848282925 0.0 0.0" />
       <axis xyz="0 1 0"/>
       <limit effort="0.0" lower="-3.14159" upper="3.14159" velocity="0.0"/>
    </joint>
    <link name="Link1Link11">
        <inertial>
            <origin xyz="-0.27086834241414626 0.0 0.0" rpy="0 0 0"/>
            <mass value="1" />
            <inertia ixx="100" ixy="0" ixz="0" iyy="100" iyz="0" izz="100" />
        </inertial>
        <visual>
            <origin xyz="-0.27086834241414626 0.0 0.0" rpy="0 0 0"/>
            <geometry>
                <box size="0.5417366848282925 0.6231566150932015 0.531598241825199" />
            </geometry>
            <material name="Green">
                <color rgba="0.25 0.76 0.50 1.0"/>
            </material>
        </visual>
        <collision>
            <origin xyz="-0.27086834241414626 0.0 0.0" rpy="0 0 0"/>
            <geometry>
                <box size="0.5417366848282925 0.6231566150932015 0.531598241825199" />
            </geometry>
        </collision>
    </link>
</robot>