<robot name = "robot">
    <link name="Link0">
        <inertial>
            <origin xyz="0 0 0.36358902176599506" rpy="0 0 0"/>
            <mass value="1" />
            <inertia ixx="100" ixy="0" ixz="0" iyy="100" iyz="0" izz="100" />
        </inertial>
        <visual>
            <origin xyz="0 0 0.36358902176599506" rpy="0 0 0"/>
            <geometry>
                <box size="1.4141398635437645 0.5769241068262209 0.7271780435319901" />
            </geometry>
            <material name="Green">
                <color rgba="0.25 0.76 0.50 1.0"/>
            </material>
        </visual>
        <collision>
            <origin xyz="0 0 0.36358902176599506" rpy="0 0 0"/>
            <geometry>
                <box size="1.4141398635437645 0.5769241068262209 0.7271780435319901" />
            </geometry>
        </collision>
    </link>
    <joint name="Link0_Link1" type="revolute">
       <parent link="Link0"/>
       <child  link="Link1"/>
       <origin rpy="0 0 0" xyz="0 0.28846205341311043 0.36358902176599506" />
       <axis xyz="0 1 0"/>
       <limit effort="0.0" lower="-3.14159" upper="3.14159" velocity="0.0"/>
    </joint>
    <link name="Link1">
        <inertial>
            <origin xyz="0 0.5697511294911806 0" rpy="0 0 0"/>
            <mass value="1" />
            <inertia ixx="100" ixy="0" ixz="0" iyy="100" iyz="0" izz="100" />
        </inertial>
        <visual>
            <origin xyz="0 0.5697511294911806 0" rpy="0 0 0"/>
            <geometry>
                <box size="0.9575765313699761 1.1395022589823611 0.6254784503619423" />
            </geometry>
            <material name="Blue">
                <color rgba="0.01 0.54 1.0 1.0"/>
            </material>
        </visual>
        <collision>
            <origin xyz="0 0.5697511294911806 0" rpy="0 0 0"/>
            <geometry>
                <box size="0.9575765313699761 1.1395022589823611 0.6254784503619423" />
            </geometry>
        </collision>
    </link>
    <joint name="Link1_Link1Link00" type="revolute">
       <parent link="Link1"/>
       <child  link="Link1Link00"/>
       <origin rpy="0 0 0" xyz="0.47878826568498806 0.5697511294911806 0.0" />
       <axis xyz="0 1 0"/>
       <limit effort="0.0" lower="-3.14159" upper="3.14159" velocity="0.0"/>
    </joint>
    <link name="Link1Link00">
        <inertial>
            <origin xyz="0.32453736011751566 0.0 0.0" rpy="0 0 0"/>
            <mass value="1" />
            <inertia ixx="100" ixy="0" ixz="0" iyy="100" iyz="0" izz="100" />
        </inertial>
        <visual>
            <origin xyz="0.32453736011751566 0.0 0.0" rpy="0 0 0"/>
            <geometry>
                <box size="0.6490747202350313 0.7267517781966488 0.8304998169185868" />
            </geometry>
            <material name="Green">
                <color rgba="0.25 0.76 0.50 1.0"/>
            </material>
        </visual>
        <collision>
            <origin xyz="0.32453736011751566 0.0 0.0" rpy="0 0 0"/>
            <geometry>
                <box size="0.6490747202350313 0.7267517781966488 0.8304998169185868" />
            </geometry>
        </collision>
    </link>
    <joint name="Link1_Link1Link10" type="revolute">
       <parent link="Link1"/>
       <child  link="Link1Link10"/>
       <origin rpy="0 0 0" xyz="-0.47878826568498806 0.5697511294911806 0.0" />
       <axis xyz="0 1 0"/>
       <limit effort="0.0" lower="-3.14159" upper="3.14159" velocity="0.0"/>
    </joint>
    <link name="Link1Link10">
        <inertial>
            <origin xyz="-0.3831212030201716 0.0 0.0" rpy="0 0 0"/>
            <mass value="1" />
            <inertia ixx="100" ixy="0" ixz="0" iyy="100" iyz="0" izz="100" />
        </inertial>
        <visual>
            <origin xyz="-0.3831212030201716 0.0 0.0" rpy="0 0 0"/>
            <geometry>
                <box size="0.7662424060403432 0.5854801472575406 0.9857977986846824" />
            </geometry>
            <material name="Blue">
                <color rgba="0.01 0.54 1.0 1.0"/>
            </material>
        </visual>
        <collision>
            <origin xyz="-0.3831212030201716 0.0 0.0" rpy="0 0 0"/>
            <geometry>
                <box size="0.7662424060403432 0.5854801472575406 0.9857977986846824" />
            </geometry>
        </collision>
    </link>
    <joint name="Link1_Link1Link20" type="revolute">
       <parent link="Link1"/>
       <child  link="Link1Link20"/>
       <origin rpy="0 0 0" xyz="0.0 0.5697511294911806 0.31273922518097114" />
       <axis xyz="0 1 0"/>
       <limit effort="0.0" lower="-3.14159" upper="3.14159" velocity="0.0"/>
    </joint>
    <link name="Link1Link20">
        <inertial>
            <origin xyz="0.0 0.0 0.29471281354766743" rpy="0 0 0"/>
            <mass value="1" />
            <inertia ixx="100" ixy="0" ixz="0" iyy="100" iyz="0" izz="100" />
        </inertial>
        <visual>
            <origin xyz="0.0 0.0 0.29471281354766743" rpy="0 0 0"/>
            <geometry>
                <box size="0.6393675413488691 0.825754538695266 0.5894256270953349" />
            </geometry>
            <material name="Blue">
                <color rgba="0.01 0.54 1.0 1.0"/>
            </material>
        </visual>
        <collision>
            <origin xyz="0.0 0.0 0.29471281354766743" rpy="0 0 0"/>
            <geometry>
                <box size="0.6393675413488691 0.825754538695266 0.5894256270953349" />
            </geometry>
        </collision>
    </link>
</robot>